<?xml version="1.0"?>

<robot xmlns:xacro="http://www.ros.org/wiki/xacro">
    <xacro:macro name="default_wheel" params="name rot">
        <link name="${name}">
            <visual>
                <geometry>
                    <!--cylinder length=".1" radius="0.13" /-->
                    <mesh filename="package://aio_robot/meshes/wheel.dae" scale="0.6 0.6 0.6" />

                </geometry>
                <origin rpy="${rot} 0 0" xyz="0 0 0.0" />
                <!--material name="red"/-->

            </visual>
            <collision>
                <geometry>
                    <mesh filename="package://aio_robot/meshes/wheel.dae" scale="0.6 0.6 0.6" />
                </geometry>
                <origin rpy="${rot} 0 0" xyz="0 0 0.0" />
                <material name="red" />
            </collision>
            <inertial>
                <origin rpy="${rot} 0 0" xyz="0 0 0" />
                <mass value="1.0" />
                <inertia ixx="0.01" ixy="0" ixz="0" iyy="0.01" iyz="0" izz="0.01" />
            </inertial>
        </link>
    </xacro:macro>
    <xacro:macro name="wheel_joint" params="child_name cenx ceny">
        <joint name="base_to_${child_name}" type="continuous">
            <axis rpy="0 0 0" xyz="0 1 0" />
            <parent link="base_link" />
            <child link="${child_name}" />
            <origin xyz="${cenx} ${ceny} -0.01" />
        </joint>

    </xacro:macro>
</robot>
